Workbook
Name agent: '[1]Raw Data'!$H:$H
Name Agent_ID: 'Required Data'!$G:$G
Name Bucket: 'Required Data'!$AC:$AC
Name Busniss_Critical: 'Required Data'!$N:$N
Name Busniss_Critical_Percentage: 'Required Data'!$O:$O
Name Call_date: 'Required Data'!$AA:$AA
Name Call_day: '[2]Required Data'!$B:$B
Name Call_day: 'Required Data'!$B:$B
Name CallHour: '[2]Required Data'!$AD:$AD
Name CallHour: 'Required Data'!$AD:$AD
Name CallWeek: 'Required Data'!$U:$U
Name Compliance_Critical: 'Required Data'!$P:$P
Name Compliance_Critical_Percentage: 'Required Data'!$Q:$Q
Name Critical_counter: 'Required Data'!$Y:$Y
Name d: #REF!
Name d: #REF!
Name DEP: 'Required Data'!$V:$V
Name ECF: '[1]Raw Data'!$AR:$AR
Name End_User_Crirical: '[2]Required Data'!$L:$L
Name End_User_Crirical: 'Required Data'!$L:$L
Name End_User_Crirical_Percentage: '[2]Required Data'!$M:$M
Name End_User_Crirical_Percentage: 'Required Data'!$M:$M
Name Evaluation_Week: 'Required Data'!$W:$W
Name Evaluator_Name: 'Required Data'!$H:$H
Name HC: [3]Sheet4!$A$1:$G$276
Name Label: INDEX(#REF!,MATCH(#REF!,#REF!,0))
Name Label: INDEX(#REF!,MATCH(#REF!,#REF!,0))
Name Label: INDEX(#REF!,MATCH(#REF!,#REF!,0))
Name Label: INDEX(#REF!,MATCH(#REF!,#REF!,0))
Name Label: INDEX(#REF!,MATCH(#REF!,#REF!,0))
Name Label: INDEX(#REF!,MATCH(#REF!,#REF!,0))
Name Label: INDEX(#REF!,MATCH(#REF!,#REF!,0))
Name Label: INDEX(#REF!,MATCH(#REF!,#REF!,0))
Name Non_Critical: '[2]Required Data'!$R:$R
Name Non_Critical: 'Required Data'!$R:$R
Name Non_Critical_Percentage: '[2]Required Data'!$S:$S
Name Non_Critical_Percentage: 'Required Data'!$S:$S
Name OnTime: [4]Sheet4!$E$12:$E$13
Name p: #REF!
Name p: #REF!
Name p: #REF!
Name p: #REF!
Name p: #REF!
Name p: #REF!
Name p: #REF!
Name p: #REF!
Name ParetoBaseCell: #REF!
Name ParetoBaseCell: #REF!
Name ParetoBaseCell: #REF!
Name ParetoBaseCell: #REF!
Name ParetoBaseCell: #REF!
Name ParetoBaseCell: #REF!
Name ParetoBaseCell: #REF!
Name ParetoBaseCell: #REF!
Name Process_Type: '[1]Raw Data'!$G:$G
Name q: #REF!
Name q: #REF!
Name q: #REF!
Name q: #REF!
Name q: #REF!

Sheet Main page

Sheet Active List
A1: Agent Name | B1: Login | C1: TL | D1: Status | E1: Certification date
A2: Ahmed Ramadan Metwally Ali | B2: 33271 | C2: mahmoud_hhamed | D2: Dismissed | E2: 45692
A3: Kerolos Adel | B3: 33281 | C3: omnia_ahelmy | D3: Dismissed | E3: 45723
A4: Ahmed Sayed Farouk Mohamed | B4: 31926 | C4: mahmoud_hhamed | D4: Dismissed | E4: 45727.675
A5: Ziad Mohamed sayd ahmed | B5: 32461 | C5: mahmoud_hhamed | D5: Dismissed | E5: 45694
A6: Julie Hany Soliman Zaky | B6: 31927 | C6: omnia_ahelmy | D6: Dismissed | E6: 45694
A7: Seif Eldeen Mohamed Mostafa Bakry | B7: 32698 | C7: omnia_ahelmy | D7: Dismissed | E7: 45761
A8: Youssif Momen Soliman Altweal | B8: 32762 | C8: mahmoud_hhamed | D8: Dismissed | E8: 45818
A9: Kareem Magdy | B9: 33277 | C9: mahmoud_hhamed | D9: IB | E9: 45692
A10: Mariam Wael Farouk | B10: 32699 | C10: omnia_ahelmy | D10: IB | E10: 45694
A11: AyaTullah Abdelkhalek ElSayed | B11: 32764 | C11: mahmoud_hhamed | D11: IB | E11: 45820
A12: Wafaa Ali Elorabi M | B12: 31144 | C12: omnia_ahelmy | D12: IB | E12: 45862
A13: Shahd Ashraf Muhamed Saber | B13: 32462 | C13: omnia_ahelmy | D13: IB | E13: 45887
... A31: Salma mohamed aly | B31: 32962 | C31: mahmoud_hhamed | D31: IB | E31: 46132

Sheet Required Data
A1: Call Id | B1: Call day | C1: Call Month | D1: Call Year | E1: Time | F1: Queue | G1: Agent ID | H1: Evaluator Name | I1: Evaluation day | J1: TargeType | K1: Result | L1: End-User Crirical | M1: End-User Crirical_Percentage | N1: Busniss Critical | O1: Busniss Critical_Percentage | P1: Compliance Critical | Q1: Compliance Critical_Percentage | R1: Non Critical | S1: Non Critical_Percentage | T1: EvaluationDate-CallDate | U1: Call Week | V1: DEP | W1: Evaluation Week | X1: TL | Y1: Critical counter | Z1: Shift | AA1: Call date | AB1: Weekday | AC1: Bucket | AD1: CallHour | AE1: Target Type Group
A2: =IF('QMS Data'!A2<>"",'QMS Data'!A2,"") -> 514010093 | B2: =IFERROR(VLOOKUP($A2,'QMS Data'!$A:$BD,MATCH(B$1,'QMS Data'!$1:$1,0),FALSE),"") -> 1 | C2: =IFERROR(VLOOKUP($A2,'QMS Data'!$A:$BD,MATCH(C$1,'QMS Data'!$1:$1,0),FALSE),"") -> 6 | D2: =IFERROR(VLOOKUP($A2,'QMS Data'!$A:$BD,MATCH(D$1,'QMS Data'!$1:$1,0),FALSE),"") -> 2026 | E2: =IFERROR(VLOOKUP($A2,'QMS Data'!$A:$BD,MATCH(E$1,'QMS Data'!$1:$1,0),FALSE),"") -> 0.53327546 | F2: =IFERROR(VLOOKUP($A2,'QMS Data'!$A:$BD,MATCH(F$1,'QMS Data'!$1:$1,0),FALSE),"") -> Tatweer Misr | G2: =IFERROR(VLOOKUP($A2,'QMS Data'!$A:$BD,MATCH(G$1,'QMS Data'!$1:$1,0),FALSE),"") -> 32462 | H2: =IFERROR(VLOOKUP($A2,'QMS Data'!$A:$BD,MATCH(H$1,'QMS Data'!$1:$1,0),FALSE),"") -> Omnia_A Helmy | I2: =IFERROR(VLOOKUP($A2,'QMS Data'!$A:$BD,MATCH(I$1,'QMS Data'!$1:$1,0),FALSE),"") -> 1 | ... S2: =IFERROR(VLOOKUP($A2,'QMS Data'!$A:$BD,MATCH(S$1,'QMS Data'!$1:$1,0),FALSE),"") -> 1 | T2: =IFERROR(I2-B2,"") -> 0 | U2: =IF(B2<>"",IF(B2>22,"W4",IF(B2>16,"W3",IF(B2>9,"W2",IF(B2>0,"W1",0)))),"") -> W1 | V2: =IFERROR(VLOOKUP('Required Data'!$H2,Evaluators!A:B,2,FALSE),"") -> Operation | W2: =IF(I2<>"",IF(I2>22,"W4",IF(I2>15,"W3",IF(I2>8,"W2",IF(I2>1,"W1",IF(I2=1,"W4",""))))),"") -> W4 | X2: =IFERROR(VLOOKUP(G2,'Active List'!B:D,2,FALSE),"") -> omnia_ahelmy | Y2: =IFERROR(SUM('Required Data'!$L2+'Required Data'!$N2+'Required Data'!$P2),"") -> 0 | Z2: =IFERROR(IF(HOUR(E2)<8,"Overnight",IF(HOUR(E2)<12,"Mornning",IF(HOUR(E2)<16,"Between",IF(HOUR(E2)<20,"Half Night","Night")))),"") -> Between | AA2: =IFERROR(DATE(Table1[[#This Row],[Call Year]],Table1[[#This Row],[Call Month]],Table1[[#This Row],[Call day]]),"") -> 46174 | AB2: =TEXT(Table1[[#This Row],[Call date]],"DDDD") -> Monday | AC2: =IFERROR(IF(Table1[[#This Row],[Call date]]-VLOOKUP(Table1[[#This Row],[Agent ID]],'Active List'!B:E,4,FALSE)>60,"old",IF(Table1[[#This Row],[Call date]]-VLOOKUP(Table1[[#This Row],[Agent ID]],'Active List'!B:E,4,FALSE)>30,"Bucket 2",IF(Table1[[#This Row],[Call date]]-VLOOKUP(Table1[[#This Row],[Agent ID]],'Active List'!B:E,4,FALSE)>0,"Bucket 1",""))),"") -> old | AD2: =IFERROR(HOUR(Table1[[#This Row],[Time]]),"") -> 12 | AE2: =IFERROR(VLOOKUP(J2,DV!A:B,2,FALSE),J2) -> Agent Level
A3: =IF('QMS Data'!A3<>"",'QMS Data'!A3,"") -> 515267273 | B3: =IFERROR(VLOOKUP($A3,'QMS Data'!$A:$BD,MATCH(B$1,'QMS Data'!$1:$1,0),FALSE),"") -> 14 | C3: =IFERROR(VLOOKUP($A3,'QMS Data'!$A:$BD,MATCH(C$1,'QMS Data'!$1:$1,0),FALSE),"") -> 6 | D3: =IFERROR(VLOOKUP($A3,'QMS Data'!$A:$BD,MATCH(D$1,'QMS Data'!$1:$1,0),FALSE),"") -> 2026 | E3: =IFERROR(VLOOKUP($A3,'QMS Data'!$A:$BD,MATCH(E$1,'QMS Data'!$1:$1,0),FALSE),"") -> 0.59328704 | F3: =IFERROR(VLOOKUP($A3,'QMS Data'!$A:$BD,MATCH(F$1,'QMS Data'!$1:$1,0),FALSE),"") -> Tatweer Misr | G3: =IFERROR(VLOOKUP($A3,'QMS Data'!$A:$BD,MATCH(G$1,'QMS Data'!$1:$1,0),FALSE),"") -> 32755 | H3: =IFERROR(VLOOKUP($A3,'QMS Data'!$A:$BD,MATCH(H$1,'QMS Data'!$1:$1,0),FALSE),"") -> Silvia_ANaguib | I3: =IFERROR(VLOOKUP($A3,'QMS Data'!$A:$BD,MATCH(I$1,'QMS Data'!$1:$1,0),FALSE),"") -> 15 | ... S3: =IFERROR(VLOOKUP($A3,'QMS Data'!$A:$BD,MATCH(S$1,'QMS Data'!$1:$1,0),FALSE),"") -> 1 | T3: =IFERROR(I3-B3,"") -> 1 | U3: =IF(B3<>"",IF(B3>22,"W4",IF(B3>16,"W3",IF(B3>9,"W2",IF(B3>0,"W1",0)))),"") -> W2 | V3: =IFERROR(VLOOKUP('Required Data'!$H3,Evaluators!A:B,2,FALSE),"") -> Quality | W3: =IF(I3<>"",IF(I3>22,"W4",IF(I3>15,"W3",IF(I3>8,"W2",IF(I3>1,"W1",IF(I3=1,"W4",""))))),"") -> W2 | X3: =IFERROR(VLOOKUP(G3,'Active List'!B:D,2,FALSE),"") | Y3: =IFERROR(SUM('Required Data'!$L3+'Required Data'!$N3+'Required Data'!$P3),"") -> 0 | Z3: =IFERROR(IF(HOUR(E3)<8,"Overnight",IF(HOUR(E3)<12,"Mornning",IF(HOUR(E3)<16,"Between",IF(HOUR(E3)<20,"Half Night","Night")))),"") -> Between | AA3: =IFERROR(DATE(Table1[[#This Row],[Call Year]],Table1[[#This Row],[Call Month]],Table1[[#This Row],[Call day]]),"") -> 46187 | AB3: =TEXT(Table1[[#This Row],[Call date]],"DDDD") -> Sunday | AC3: =IFERROR(IF(Table1[[#This Row],[Call date]]-VLOOKUP(Table1[[#This Row],[Agent ID]],'Active List'!B:E,4,FALSE)>60,"old",IF(Table1[[#This Row],[Call date]]-VLOOKUP(Table1[[#This Row],[Agent ID]],'Active List'!B:E,4,FALSE)>30,"Bucket 2",IF(Table1[[#This Row],[Call date]]-VLOOKUP(Table1[[#This Row],[Agent ID]],'Active List'!B:E,4,FALSE)>0,"Bucket 1",""))),"") | AD3: =IFERROR(HOUR(Table1[[#This Row],[Time]]),"") -> 14 | AE3: =IFERROR(VLOOKUP(J3,DV!A:B,2,FALSE),J3) -> Agent Level
A4: =IF('QMS Data'!A4<>"",'QMS Data'!A4,"") -> 515278813 | B4: =IFERROR(VLOOKUP($A4,'QMS Data'!$A:$BD,MATCH(B$1,'QMS Data'!$1:$1,0),FALSE),"") -> 14 | C4: =IFERROR(VLOOKUP($A4,'QMS Data'!$A:$BD,MATCH(C$1,'QMS Data'!$1:$1,0),FALSE),"") -> 6 | D4: =IFERROR(VLOOKUP($A4,'QMS Data'!$A:$BD,MATCH(D$1,'QMS Data'!$1:$1,0),FALSE),"") -> 2026 | E4: =IFERROR(VLOOKUP($A4,'QMS Data'!$A:$BD,MATCH(E$1,'QMS Data'!$1:$1,0),FALSE),"") -> 0.63731481 | F4: =IFERROR(VLOOKUP($A4,'QMS Data'!$A:$BD,MATCH(F$1,'QMS Data'!$1:$1,0),FALSE),"") -> Tatweer Misr | G4: =IFERROR(VLOOKUP($A4,'QMS Data'!$A:$BD,MATCH(G$1,'QMS Data'!$1:$1,0),FALSE),"") -> 32755 | H4: =IFERROR(VLOOKUP($A4,'QMS Data'!$A:$BD,MATCH(H$1,'QMS Data'!$1:$1,0),FALSE),"") -> Silvia_ANaguib | I4: =IFERROR(VLOOKUP($A4,'QMS Data'!$A:$BD,MATCH(I$1,'QMS Data'!$1:$1,0),FALSE),"") -> 15 | ... S4: =IFERROR(VLOOKUP($A4,'QMS Data'!$A:$BD,MATCH(S$1,'QMS Data'!$1:$1,0),FALSE),"") -> 1 | T4: =IFERROR(I4-B4,"") -> 1 | U4: =IF(B4<>"",IF(B4>22,"W4",IF(B4>16,"W3",IF(B4>9,"W2",IF(B4>0,"W1",0)))),"") -> W2 | V4: =IFERROR(VLOOKUP('Required Data'!$H4,Evaluators!A:B,2,FALSE),"") -> Quality | W4: =IF(I4<>"",IF(I4>22,"W4",IF(I4>15,"W3",IF(I4>8,"W2",IF(I4>1,"W1",IF(I4=1,"W4",""))))),"") -> W2 | X4: =IFERROR(VLOOKUP(G4,'Active List'!B:D,2,FALSE),"") | Y4: =IFERROR(SUM('Required Data'!$L4+'Required Data'!$N4+'Required Data'!$P4),"") -> 0 | Z4: =IFERROR(IF(HOUR(E4)<8,"Overnight",IF(HOUR(E4)<12,"Mornning",IF(HOUR(E4)<16,"Between",IF(HOUR(E4)<20,"Half Night","Night")))),"") -> Between | AA4: =IFERROR(DATE(Table1[[#This Row],[Call Year]],Table1[[#This Row],[Call Month]],Table1[[#This Row],[Call day]]),"") -> 46187 | AB4: =TEXT(Table1[[#This Row],[Call date]],"DDDD") -> Sunday | AC4: =IFERROR(IF(Table1[[#This Row],[Call date]]-VLOOKUP(Table1[[#This Row],[Agent ID]],'Active List'!B:E,4,FALSE)>60,"old",IF(Table1[[#This Row],[Call date]]-VLOOKUP(Table1[[#This Row],[Agent ID]],'Active List'!B:E,4,FALSE)>30,"Bucket 2",IF(Table1[[#This Row],[Call date]]-VLOOKUP(Table1[[#This Row],[Agent ID]],'Active List'!B:E,4,FALSE)>0,"Bucket 1",""))),"") | AD4: =IFERROR(HOUR(Table1[[#This Row],[Time]]),"") -> 15 | AE4: =IFERROR(VLOOKUP(J4,DV!A:B,2,FALSE),J4) -> Agent Level
A5: =IF('QMS Data'!A5<>"",'QMS Data'!A5,"") -> 515580495 | B5: =IFERROR(VLOOKUP($A5,'QMS Data'!$A:$BD,MATCH(B$1,'QMS Data'!$1:$1,0),FALSE),"") -> 17 | C5: =IFERROR(VLOOKUP($A5,'QMS Data'!$A:$BD,MATCH(C$1,'QMS Data'!$1:$1,0),FALSE),"") -> 6 | D5: =IFERROR(VLOOKUP($A5,'QMS Data'!$A:$BD,MATCH(D$1,'QMS Data'!$1:$1,0),FALSE),"") -> 2026 | E5: =IFERROR(VLOOKUP($A5,'QMS Data'!$A:$BD,MATCH(E$1,'QMS Data'!$1:$1,0),FALSE),"") -> 0.43489583 | F5: =IFERROR(VLOOKUP($A5,'QMS Data'!$A:$BD,MATCH(F$1,'QMS Data'!$1:$1,0),FALSE),"") -> Tatweer Misr | G5: =IFERROR(VLOOKUP($A5,'QMS Data'!$A:$BD,MATCH(G$1,'QMS Data'!$1:$1,0),FALSE),"") -> 32767 | H5: =IFERROR(VLOOKUP($A5,'QMS Data'!$A:$BD,MATCH(H$1,'QMS Data'!$1:$1,0),FALSE),"") -> Silvia_ANaguib | I5: =IFERROR(VLOOKUP($A5,'QMS Data'!$A:$BD,MATCH(I$1,'QMS Data'!$1:$1,0),FALSE),"") -> 18 | ... S5: =IFERROR(VLOOKUP($A5,'QMS Data'!$A:$BD,MATCH(S$1,'QMS Data'!$1:$1,0),FALSE),"") -> 1 | T5: =IFERROR(I5-B5,"") -> 1 | U5: =IF(B5<>"",IF(B5>22,"W4",IF(B5>16,"W3",IF(B5>9,"W2",IF(B5>0,"W1",0)))),"") -> W3 | V5: =IFERROR(VLOOKUP('Required Data'!$H5,Evaluators!A:B,2,FALSE),"") -> Quality | W5: =IF(I5<>"",IF(I5>22,"W4",IF(I5>15,"W3",IF(I5>8,"W2",IF(I5>1,"W1",IF(I5=1,"W4",""))))),"") -> W3 | X5: =IFERROR(VLOOKUP(G5,'Active List'!B:D,2,FALSE),"") | Y5: =IFERROR(SUM('Required Data'!$L5+'Required Data'!$N5+'Required Data'!$P5),"") -> 0 | Z5: =IFERROR(IF(HOUR(E5)<8,"Overnight",IF(HOUR(E5)<12,"Mornning",IF(HOUR(E5)<16,"Between",IF(HOUR(E5)<20,"Half Night","Night")))),"") -> Mornning | AA5: =IFERROR(DATE(Table1[[#This Row],[Call Year]],Table1[[#This Row],[Call Month]],Table1[[#This Row],[Call day]]),"") -> 46190 | AB5: =TEXT(Table1[[#This Row],[Call date]],"DDDD") -> Wednesday | AC5: =IFERROR(IF(Table1[[#This Row],[Call date]]-VLOOKUP(Table1[[#This Row],[Agent ID]],'Active List'!B:E,4,FALSE)>60,"old",IF(Table1[[#This Row],[Call date]]-VLOOKUP(Table1[[#This Row],[Agent ID]],'Active List'!B:E,4,FALSE)>30,"Bucket 2",IF(Table1[[#This Row],[Call date]]-VLOOKUP(Table1[[#This Row],[Agent ID]],'Active List'!B:E,4,FALSE)>0,"Bucket 1",""))),"") | AD5: =IFERROR(HOUR(Table1[[#This Row],[Time]]),"") -> 10 | AE5: =IFERROR(VLOOKUP(J5,DV!A:B,2,FALSE),J5) -> Agent Level
A6: =IF('QMS Data'!A6<>"",'QMS Data'!A6,"") -> 515013664 | B6: =IFERROR(VLOOKUP($A6,'QMS Data'!$A:$BD,MATCH(B$1,'QMS Data'!$1:$1,0),FALSE),"") -> 11 | C6: =IFERROR(VLOOKUP($A6,'QMS Data'!$A:$BD,MATCH(C$1,'QMS Data'!$1:$1,0),FALSE),"") -> 6 | D6: =IFERROR(VLOOKUP($A6,'QMS Data'!$A:$BD,MATCH(D$1,'QMS Data'!$1:$1,0),FALSE),"") -> 2026 | E6: =IFERROR(VLOOKUP($A6,'QMS Data'!$A:$BD,MATCH(E$1,'QMS Data'!$1:$1,0),FALSE),"") -> 0.62005787 | F6: =IFERROR(VLOOKUP($A6,'QMS Data'!$A:$BD,MATCH(F$1,'QMS Data'!$1:$1,0),FALSE),"") -> Tatweer Misr | G6: =IFERROR(VLOOKUP($A6,'QMS Data'!$A:$BD,MATCH(G$1,'QMS Data'!$1:$1,0),FALSE),"") -> 33277 | H6: =IFERROR(VLOOKUP($A6,'QMS Data'!$A:$BD,MATCH(H$1,'QMS Data'!$1:$1,0),FALSE),"") -> Silvia_ANaguib | I6: =IFERROR(VLOOKUP($A6,'QMS Data'!$A:$BD,MATCH(I$1,'QMS Data'!$1:$1,0),FALSE),"") -> 12 | ... S6: =IFERROR(VLOOKUP($A6,'QMS Data'!$A:$BD,MATCH(S$1,'QMS Data'!$1:$1,0),FALSE),"") -> 0.875 | T6: =IFERROR(I6-B6,"") -> 1 | U6: =IF(B6<>"",IF(B6>22,"W4",IF(B6>16,"W3",IF(B6>9,"W2",IF(B6>0,"W1",0)))),"") -> W2 | V6: =IFERROR(VLOOKUP('Required Data'!$H6,Evaluators!A:B,2,FALSE),"") -> Quality | W6: =IF(I6<>"",IF(I6>22,"W4",IF(I6>15,"W3",IF(I6>8,"W2",IF(I6>1,"W1",IF(I6=1,"W4",""))))),"") -> W2 | X6: =IFERROR(VLOOKUP(G6,'Active List'!B:D,2,FALSE),"") -> mahmoud_hhamed | Y6: =IFERROR(SUM('Required Data'!$L6+'Required Data'!$N6+'Required Data'!$P6),"") -> 0 | Z6: =IFERROR(IF(HOUR(E6)<8,"Overnight",IF(HOUR(E6)<12,"Mornning",IF(HOUR(E6)<16,"Between",IF(HOUR(E6)<20,"Half Night","Night")))),"") -> Between | AA6: =IFERROR(DATE(Table1[[#This Row],[Call Year]],Table1[[#This Row],[Call Month]],Table1[[#This Row],[Call day]]),"") -> 46184 | AB6: =TEXT(Table1[[#This Row],[Call date]],"DDDD") -> Thursday | AC6: =IFERROR(IF(Table1[[#This Row],[Call date]]-VLOOKUP(Table1[[#This Row],[Agent ID]],'Active List'!B:E,4,FALSE)>60,"old",IF(Table1[[#This Row],[Call date]]-VLOOKUP(Table1[[#This Row],[Agent ID]],'Active List'!B:E,4,FALSE)>30,"Bucket 2",IF(Table1[[#This Row],[Call date]]-VLOOKUP(Table1[[#This Row],[Agent ID]],'Active List'!B:E,4,FALSE)>0,"Bucket 1",""))),"") -> old | AD6: =IFERROR(HOUR(Table1[[#This Row],[Time]]),"") -> 14 | AE6: =IFERROR(VLOOKUP(J6,DV!A:B,2,FALSE),J6) -> Agent Level
A7: =IF('QMS Data'!A7<>"",'QMS Data'!A7,"") -> 515288065 | B7: =IFERROR(VLOOKUP($A7,'QMS Data'!$A:$BD,MATCH(B$1,'QMS Data'!$1:$1,0),FALSE),"") -> 14 | C7: =IFERROR(VLOOKUP($A7,'QMS Data'!$A:$BD,MATCH(C$1,'QMS Data'!$1:$1,0),FALSE),"") -> 6 | D7: =IFERROR(VLOOKUP($A7,'QMS Data'!$A:$BD,MATCH(D$1,'QMS Data'!$1:$1,0),FALSE),"") -> 2026 | E7: =IFERROR(VLOOKUP($A7,'QMS Data'!$A:$BD,MATCH(E$1,'QMS Data'!$1:$1,0),FALSE),"") -> 0.67179398 | F7: =IFERROR(VLOOKUP($A7,'QMS Data'!$A:$BD,MATCH(F$1,'QMS Data'!$1:$1,0),FALSE),"") -> Tatweer Misr | G7: =IFERROR(VLOOKUP($A7,'QMS Data'!$A:$BD,MATCH(G$1,'QMS Data'!$1:$1,0),FALSE),"") -> 33271 | H7: =IFERROR(VLOOKUP($A7,'QMS Data'!$A:$BD,MATCH(H$1,'QMS Data'!$1:$1,0),FALSE),"") -> Silvia_ANaguib | I7: =IFERROR(VLOOKUP($A7,'QMS Data'!$A:$BD,MATCH(I$1,'QMS Data'!$1:$1,0),FALSE),"") -> 15 | ... S7: =IFERROR(VLOOKUP($A7,'QMS Data'!$A:$BD,MATCH(S$1,'QMS Data'!$1:$1,0),FALSE),"") -> 1 | T7: =IFERROR(I7-B7,"") -> 1 | U7: =IF(B7<>"",IF(B7>22,"W4",IF(B7>16,"W3",IF(B7>9,"W2",IF(B7>0,"W1",0)))),"") -> W2 | V7: =IFERROR(VLOOKUP('Required Data'!$H7,Evaluators!A:B,2,FALSE),"") -> Quality | W7: =IF(I7<>"",IF(I7>22,"W4",IF(I7>15,"W3",IF(I7>8,"W2",IF(I7>1,"W1",IF(I7=1,"W4",""))))),"") -> W2 | X7: =IFERROR(VLOOKUP(G7,'Active List'!B:D,2,FALSE),"") -> mahmoud_hhamed | Y7: =IFERROR(SUM('Required Data'!$L7+'Required Data'!$N7+'Required Data'!$P7),"") -> 0 | Z7: =IFERROR(IF(HOUR(E7)<8,"Overnight",IF(HOUR(E7)<12,"Mornning",IF(HOUR(E7)<16,"Between",IF(HOUR(E7)<20,"Half Night","Night")))),"") -> Half Night | AA7: =IFERROR(DATE(Table1[[#This Row],[Call Year]],Table1[[#This Row],[Call Month]],Table1[[#This Row],[Call day]]),"") -> 46187 | AB7: =TEXT(Table1[[#This Row],[Call date]],"DDDD") -> Sunday | AC7: =IFERROR(IF(Table1[[#This Row],[Call date]]-VLOOKUP(Table1[[#This Row],[Agent ID]],'Active List'!B:E,4,FALSE)>60,"old",IF(Table1[[#This Row],[Call date]]-VLOOKUP(Table1[[#This Row],[Agent ID]],'Active List'!B:E,4,FALSE)>30,"Bucket 2",IF(Table1[[#This Row],[Call date]]-VLOOKUP(Table1[[#This Row],[Agent ID]],'Active List'!B:E,4,FALSE)>0,"Bucket 1",""))),"") -> old | AD7: =IFERROR(HOUR(Table1[[#This Row],[Time]]),"") -> 16 | AE7: =IFERROR(VLOOKUP(J7,DV!A:B,2,FALSE),J7) -> Agent Level
A8: =IF('QMS Data'!A8<>"",'QMS Data'!A8,"") -> 515308820 | B8: =IFERROR(VLOOKUP($A8,'QMS Data'!$A:$BD,MATCH(B$1,'QMS Data'!$1:$1,0),FALSE),"") -> 14 | C8: =IFERROR(VLOOKUP($A8,'QMS Data'!$A:$BD,MATCH(C$1,'QMS Data'!$1:$1,0),FALSE),"") -> 6 | D8: =IFERROR(VLOOKUP($A8,'QMS Data'!$A:$BD,MATCH(D$1,'QMS Data'!$1:$1,0),FALSE),"") -> 2026 | E8: =IFERROR(VLOOKUP($A8,'QMS Data'!$A:$BD,MATCH(E$1,'QMS Data'!$1:$1,0),FALSE),"") -> 0.78024306 | F8: =IFERROR(VLOOKUP($A8,'QMS Data'!$A:$BD,MATCH(F$1,'QMS Data'!$1:$1,0),FALSE),"") -> Tatweer Misr | G8: =IFERROR(VLOOKUP($A8,'QMS Data'!$A:$BD,MATCH(G$1,'QMS Data'!$1:$1,0),FALSE),"") -> 33271 | H8: =IFERROR(VLOOKUP($A8,'QMS Data'!$A:$BD,MATCH(H$1,'QMS Data'!$1:$1,0),FALSE),"") -> Silvia_ANaguib | I8: =IFERROR(VLOOKUP($A8,'QMS Data'!$A:$BD,MATCH(I$1,'QMS Data'!$1:$1,0),FALSE),"") -> 15 | ... S8: =IFERROR(VLOOKUP($A8,'QMS Data'!$A:$BD,MATCH(S$1,'QMS Data'!$1:$1,0),FALSE),"") -> 1 | T8: =IFERROR(I8-B8,"") -> 1 | U8: =IF(B8<>"",IF(B8>22,"W4",IF(B8>16,"W3",IF(B8>9,"W2",IF(B8>0,"W1",0)))),"") -> W2 | V8: =IFERROR(VLOOKUP('Required Data'!$H8,Evaluators!A:B,2,FALSE),"") -> Quality | W8: =IF(I8<>"",IF(I8>22,"W4",IF(I8>15,"W3",IF(I8>8,"W2",IF(I8>1,"W1",IF(I8=1,"W4",""))))),"") -> W2 | X8: =IFERROR(VLOOKUP(G8,'Active List'!B:D,2,FALSE),"") -> mahmoud_hhamed | Y8: =IFERROR(SUM('Required Data'!$L8+'Required Data'!$N8+'Required Data'!$P8),"") -> 0 | Z8: =IFERROR(IF(HOUR(E8)<8,"Overnight",IF(HOUR(E8)<12,"Mornning",IF(HOUR(E8)<16,"Between",IF(HOUR(E8)<20,"Half Night","Night")))),"") -> Half Night | AA8: =IFERROR(DATE(Table1[[#This Row],[Call Year]],Table1[[#This Row],[Call Month]],Table1[[#This Row],[Call day]]),"") -> 46187 | AB8: =TEXT(Table1[[#This Row],[Call date]],"DDDD") -> Sunday | AC8: =IFERROR(IF(Table1[[#This Row],[Call date]]-VLOOKUP(Table1[[#This Row],[Agent ID]],'Active List'!B:E,4,FALSE)>60,"old",IF(Table1[[#This Row],[Call date]]-VLOOKUP(Table1[[#This Row],[Agent ID]],'Active List'!B:E,4,FALSE)>30,"Bucket 2",IF(Table1[[#This Row],[Call date]]-VLOOKUP(Table1[[#This Row],[Agent ID]],'Active List'!B:E,4,FALSE)>0,"Bucket 1",""))),"") -> old | AD8: =IFERROR(HOUR(Table1[[#This Row],[Time]]),"") -> 18 | AE8: =IFERROR(VLOOKUP(J8,DV!A:B,2,FALSE),J8) -> Agent Level
A9: =IF('QMS Data'!A9<>"",'QMS Data'!A9,"") -> 514867960 | B9: =IFERROR(VLOOKUP($A9,'QMS Data'!$A:$BD,MATCH(B$1,'QMS Data'!$1:$1,0),FALSE),"") -> 10 | C9: =IFERROR(VLOOKUP($A9,'QMS Data'!$A:$BD,MATCH(C$1,'QMS Data'!$1:$1,0),FALSE),"") -> 6 | D9: =IFERROR(VLOOKUP($A9,'QMS Data'!$A:$BD,MATCH(D$1,'QMS Data'!$1:$1,0),FALSE),"") -> 2026 | E9: =IFERROR(VLOOKUP($A9,'QMS Data'!$A:$BD,MATCH(E$1,'QMS Data'!$1:$1,0),FALSE),"") -> 0.45792824 | F9: =IFERROR(VLOOKUP($A9,'QMS Data'!$A:$BD,MATCH(F$1,'QMS Data'!$1:$1,0),FALSE),"") -> Tatweer Misr | G9: =IFERROR(VLOOKUP($A9,'QMS Data'!$A:$BD,MATCH(G$1,'QMS Data'!$1:$1,0),FALSE),"") -> 31924 | H9: =IFERROR(VLOOKUP($A9,'QMS Data'!$A:$BD,MATCH(H$1,'QMS Data'!$1:$1,0),FALSE),"") -> Silvia_ANaguib | I9: =IFERROR(VLOOKUP($A9,'QMS Data'!$A:$BD,MATCH(I$1,'QMS Data'!$1:$1,0),FALSE),"") -> 12 | ... S9: =IFERROR(VLOOKUP($A9,'QMS Data'!$A:$BD,MATCH(S$1,'QMS Data'!$1:$1,0),FALSE),"") -> 0.875 | T9: =IFERROR(I9-B9,"") -> 2 | U9: =IF(B9<>"",IF(B9>22,"W4",IF(B9>16,"W3",IF(B9>9,"W2",IF(B9>0,"W1",0)))),"") -> W2 | V9: =IFERROR(VLOOKUP('Required Data'!$H9,Evaluators!A:B,2,FALSE),"") -> Quality | W9: =IF(I9<>"",IF(I9>22,"W4",IF(I9>15,"W3",IF(I9>8,"W2",IF(I9>1,"W1",IF(I9=1,"W4",""))))),"") -> W2 | X9: =IFERROR(VLOOKUP(G9,'Active List'!B:D,2,FALSE),"") -> omnia_ahelmy | Y9: =IFERROR(SUM('Required Data'!$L9+'Required Data'!$N9+'Required Data'!$P9),"") -> 0 | Z9: =IFERROR(IF(HOUR(E9)<8,"Overnight",IF(HOUR(E9)<12,"Mornning",IF(HOUR(E9)<16,"Between",IF(HOUR(E9)<20,"Half Night","Night")))),"") -> Mornning | AA9: =IFERROR(DATE(Table1[[#This Row],[Call Year]],Table1[[#This Row],[Call Month]],Table1[[#This Row],[Call day]]),"") -> 46183 | AB9: =TEXT(Table1[[#This Row],[Call date]],"DDDD") -> Wednesday | AC9: =IFERROR(IF(Table1[[#This Row],[Call date]]-VLOOKUP(Table1[[#This Row],[Agent ID]],'Active List'!B:E,4,FALSE)>60,"old",IF(Table1[[#This Row],[Call date]]-VLOOKUP(Table1[[#This Row],[Agent ID]],'Active List'!B:E,4,FALSE)>30,"Bucket 2",IF(Table1[[#This Row],[Call date]]-VLOOKUP(Table1[[#This Row],[Agent ID]],'Active List'!B:E,4,FALSE)>0,"Bucket 1",""))),"") -> old | AD9: =IFERROR(HOUR(Table1[[#This Row],[Time]]),"") -> 10 | AE9: =IFERROR(VLOOKUP(J9,DV!A:B,2,FALSE),J9) -> Agent Level
A10: =IF('QMS Data'!A10<>"",'QMS Data'!A10,"") -> 514861967 | B10: =IFERROR(VLOOKUP($A10,'QMS Data'!$A:$BD,MATCH(B$1,'QMS Data'!$1:$1,0),FALSE),"") -> 10 | C10: =IFERROR(VLOOKUP($A10,'QMS Data'!$A:$BD,MATCH(C$1,'QMS Data'!$1:$1,0),FALSE),"") -> 6 | D10: =IFERROR(VLOOKUP($A10,'QMS Data'!$A:$BD,MATCH(D$1,'QMS Data'!$1:$1,0),FALSE),"") -> 2026 | E10: =IFERROR(VLOOKUP($A10,'QMS Data'!$A:$BD,MATCH(E$1,'QMS Data'!$1:$1,0),FALSE),"") -> 0.42003472 | F10: =IFERROR(VLOOKUP($A10,'QMS Data'!$A:$BD,MATCH(F$1,'QMS Data'!$1:$1,0),FALSE),"") -> Tatweer Misr | G10: =IFERROR(VLOOKUP($A10,'QMS Data'!$A:$BD,MATCH(G$1,'QMS Data'!$1:$1,0),FALSE),"") -> 32962 | H10: =IFERROR(VLOOKUP($A10,'QMS Data'!$A:$BD,MATCH(H$1,'QMS Data'!$1:$1,0),FALSE),"") -> Silvia_ANaguib | I10: =IFERROR(VLOOKUP($A10,'QMS Data'!$A:$BD,MATCH(I$1,'QMS Data'!$1:$1,0),FALSE),"") -> 12 | ... S10: =IFERROR(VLOOKUP($A10,'QMS Data'!$A:$BD,MATCH(S$1,'QMS Data'!$1:$1,0),FALSE),"") -> 1 | T10: =IFERROR(I10-B10,"") -> 2 | U10: =IF(B10<>"",IF(B10>22,"W4",IF(B10>16,"W3",IF(B10>9,"W2",IF(B10>0,"W1",0)))),"") -> W2 | V10: =IFERROR(VLOOKUP('Required Data'!$H10,Evaluators!A:B,2,FALSE),"") -> Quality | W10: =IF(I10<>"",IF(I10>22,"W4",IF(I10>15,"W3",IF(I10>8,"W2",IF(I10>1,"W1",IF(I10=1,"W4",""))))),"") -> W2 | X10: =IFERROR(VLOOKUP(G10,'Active List'!B:D,2,FALSE),"") -> mahmoud_hhamed | Y10: =IFERROR(SUM('Required Data'!$L10+'Required Data'!$N10+'Required Data'!$P10),"") -> 0 | Z10: =IFERROR(IF(HOUR(E10)<8,"Overnight",IF(HOUR(E10)<12,"Mornning",IF(HOUR(E10)<16,"Between",IF(HOUR(E10)<20,"Half Night","Night")))),"") -> Mornning | AA10: =IFERROR(DATE(Table1[[#This Row],[Call Year]],Table1[[#This Row],[Call Month]],Table1[[#This Row],[Call day]]),"") -> 46183 | AB10: =TEXT(Table1[[#This Row],[Call date]],"DDDD") -> Wednesday | AC10: =IFERROR(IF(Table1[[#This Row],[Call date]]-VLOOKUP(Table1[[#This Row],[Agent ID]],'Active List'!B:E,4,FALSE)>60,"old",IF(Table1[[#This Row],[Call date]]-VLOOKUP(Table1[[#This Row],[Agent ID]],'Active List'!B:E,4,FALSE)>30,"Bucket 2",IF(Table1[[#This Row],[Call date]]-VLOOKUP(Table1[[#This Row],[Agent ID]],'Active List'!B:E,4,FALSE)>0,"Bucket 1",""))),"") -> Bucket 2 | AD10: =IFERROR(HOUR(Table1[[#This Row],[Time]]),"") -> 10 | AE10: =IFERROR(VLOOKUP(J10,DV!A:B,2,FALSE),J10) -> Agent Level
A11: =IF('QMS Data'!A11<>"",'QMS Data'!A11,"") -> 514871947 | B11: =IFERROR(VLOOKUP($A11,'QMS Data'!$A:$BD,MATCH(B$1,'QMS Data'!$1:$1,0),FALSE),"") -> 10 | C11: =IFERROR(VLOOKUP($A11,'QMS Data'!$A:$BD,MATCH(C$1,'QMS Data'!$1:$1,0),FALSE),"") -> 6 | D11: =IFERROR(VLOOKUP($A11,'QMS Data'!$A:$BD,MATCH(D$1,'QMS Data'!$1:$1,0),FALSE),"") -> 2026 | E11: =IFERROR(VLOOKUP($A11,'QMS Data'!$A:$BD,MATCH(E$1,'QMS Data'!$1:$1,0),FALSE),"") -> 0.4780787 | F11: =IFERROR(VLOOKUP($A11,'QMS Data'!$A:$BD,MATCH(F$1,'QMS Data'!$1:$1,0),FALSE),"") -> Tatweer Misr | G11: =IFERROR(VLOOKUP($A11,'QMS Data'!$A:$BD,MATCH(G$1,'QMS Data'!$1:$1,0),FALSE),"") -> 32462 | H11: =IFERROR(VLOOKUP($A11,'QMS Data'!$A:$BD,MATCH(H$1,'QMS Data'!$1:$1,0),FALSE),"") -> Silvia_ANaguib | I11: =IFERROR(VLOOKUP($A11,'QMS Data'!$A:$BD,MATCH(I$1,'QMS Data'!$1:$1,0),FALSE),"") -> 12 | ... S11: =IFERROR(VLOOKUP($A11,'QMS Data'!$A:$BD,MATCH(S$1,'QMS Data'!$1:$1,0),FALSE),"") -> 1 | T11: =IFERROR(I11-B11,"") -> 2 | U11: =IF(B11<>"",IF(B11>22,"W4",IF(B11>16,"W3",IF(B11>9,"W2",IF(B11>0,"W1",0)))),"") -> W2 | V11: =IFERROR(VLOOKUP('Required Data'!$H11,Evaluators!A:B,2,FALSE),"") -> Quality | W11: =IF(I11<>"",IF(I11>22,"W4",IF(I11>15,"W3",IF(I11>8,"W2",IF(I11>1,"W1",IF(I11=1,"W4",""))))),"") -> W2 | X11: =IFERROR(VLOOKUP(G11,'Active List'!B:D,2,FALSE),"") -> omnia_ahelmy | Y11: =IFERROR(SUM('Required Data'!$L11+'Required Data'!$N11+'Required Data'!$P11),"") -> 0 | Z11: =IFERROR(IF(HOUR(E11)<8,"Overnight",IF(HOUR(E11)<12,"Mornning",IF(HOUR(E11)<16,"Between",IF(HOUR(E11)<20,"Half Night","Night")))),"") -> Mornning | AA11: =IFERROR(DATE(Table1[[#This Row],[Call Year]],Table1[[#This Row],[Call Month]],Table1[[#This Row],[Call day]]),"") -> 46183 | AB11: =TEXT(Table1[[#This Row],[Call date]],"DDDD") -> Wednesday | AC11: =IFERROR(IF(Table1[[#This Row],[Call date]]-VLOOKUP(Table1[[#This Row],[Agent ID]],'Active List'!B:E,4,FALSE)>60,"old",IF(Table1[[#This Row],[Call date]]-VLOOKUP(Table1[[#This Row],[Agent ID]],'Active List'!B:E,4,FALSE)>30,"Bucket 2",IF(Table1[[#This Row],[Call date]]-VLOOKUP(Table1[[#This Row],[Agent ID]],'Active List'!B:E,4,FALSE)>0,"Bucket 1",""))),"") -> old | AD11: =IFERROR(HOUR(Table1[[#This Row],[Time]]),"") -> 11 | AE11: =IFERROR(VLOOKUP(J11,DV!A:B,2,FALSE),J11) -> Agent Level
A12: =IF('QMS Data'!A12<>"",'QMS Data'!A12,"") -> 514904778 | B12: =IFERROR(VLOOKUP($A12,'QMS Data'!$A:$BD,MATCH(B$1,'QMS Data'!$1:$1,0),FALSE),"") -> 10 | C12: =IFERROR(VLOOKUP($A12,'QMS Data'!$A:$BD,MATCH(C$1,'QMS Data'!$1:$1,0),FALSE),"") -> 6 | D12: =IFERROR(VLOOKUP($A12,'QMS Data'!$A:$BD,MATCH(D$1,'QMS Data'!$1:$1,0),FALSE),"") -> 2026 | E12: =IFERROR(VLOOKUP($A12,'QMS Data'!$A:$BD,MATCH(E$1,'QMS Data'!$1:$1,0),FALSE),"") -> 0.63818287 | F12: =IFERROR(VLOOKUP($A12,'QMS Data'!$A:$BD,MATCH(F$1,'QMS Data'!$1:$1,0),FALSE),"") -> Tatweer Misr | G12: =IFERROR(VLOOKUP($A12,'QMS Data'!$A:$BD,MATCH(G$1,'QMS Data'!$1:$1,0),FALSE),"") -> 33270 | H12: =IFERROR(VLOOKUP($A12,'QMS Data'!$A:$BD,MATCH(H$1,'QMS Data'!$1:$1,0),FALSE),"") -> Silvia_ANaguib | I12: =IFERROR(VLOOKUP($A12,'QMS Data'!$A:$BD,MATCH(I$1,'QMS Data'!$1:$1,0),FALSE),"") -> 12 | ... S12: =IFERROR(VLOOKUP($A12,'QMS Data'!$A:$BD,MATCH(S$1,'QMS Data'!$1:$1,0),FALSE),"") -> 1 | T12: =IFERROR(I12-B12,"") -> 2 | U12: =IF(B12<>"",IF(B12>22,"W4",IF(B12>16,"W3",IF(B12>9,"W2",IF(B12>0,"W1",0)))),"") -> W2 | V12: =IFERROR(VLOOKUP('Required Data'!$H12,Evaluators!A:B,2,FALSE),"") -> Quality | W12: =IF(I12<>"",IF(I12>22,"W4",IF(I12>15,"W3",IF(I12>8,"W2",IF(I12>1,"W1",IF(I12=1,"W4",""))))),"") -> W2 | X12: =IFERROR(VLOOKUP(G12,'Active List'!B:D,2,FALSE),"") -> mahmoud_hhamed | Y12: =IFERROR(SUM('Required Data'!$L12+'Required Data'!$N12+'Required Data'!$P12),"") -> 0 | Z12: =IFERROR(IF(HOUR(E12)<8,"Overnight",IF(HOUR(E12)<12,"Mornning",IF(HOUR(E12)<16,"Between",IF(HOUR(E12)<20,"Half Night","Night")))),"") -> Between | AA12: =IFERROR(DATE(Table1[[#This Row],[Call Year]],Table1[[#This Row],[Call Month]],Table1[[#This Row],[Call day]]),"") -> 46183 | AB12: =TEXT(Table1[[#This Row],[Call date]],"DDDD") -> Wednesday | AC12: =IFERROR(IF(Table1[[#This Row],[Call date]]-VLOOKUP(Table1[[#This Row],[Agent ID]],'Active List'!B:E,4,FALSE)>60,"old",IF(Table1[[#This Row],[Call date]]-VLOOKUP(Table1[[#This Row],[Agent ID]],'Active List'!B:E,4,FALSE)>30,"Bucket 2",IF(Table1[[#This Row],[Call date]]-VLOOKUP(Table1[[#This Row],[Agent ID]],'Active List'!B:E,4,FALSE)>0,"Bucket 1",""))),"") -> old | AD12: =IFERROR(HOUR(Table1[[#This Row],[Time]]),"") -> 15 | AE12: =IFERROR(VLOOKUP(J12,DV!A:B,2,FALSE),J12) -> Agent Level
A13: =IF('QMS Data'!A13<>"",'QMS Data'!A13,"") -> 514741104 | B13: =IFERROR(VLOOKUP($A13,'QMS Data'!$A:$BD,MATCH(B$1,'QMS Data'!$1:$1,0),FALSE),"") -> 9 | C13: =IFERROR(VLOOKUP($A13,'QMS Data'!$A:$BD,MATCH(C$1,'QMS Data'!$1:$1,0),FALSE),"") -> 6 | D13: =IFERROR(VLOOKUP($A13,'QMS Data'!$A:$BD,MATCH(D$1,'QMS Data'!$1:$1,0),FALSE),"") -> 2026 | E13: =IFERROR(VLOOKUP($A13,'QMS Data'!$A:$BD,MATCH(E$1,'QMS Data'!$1:$1,0),FALSE),"") -> 0.13244213 | F13: =IFERROR(VLOOKUP($A13,'QMS Data'!$A:$BD,MATCH(F$1,'QMS Data'!$1:$1,0),FALSE),"") -> Proper T | G13: =IFERROR(VLOOKUP($A13,'QMS Data'!$A:$BD,MATCH(G$1,'QMS Data'!$1:$1,0),FALSE),"") -> 39025 | H13: =IFERROR(VLOOKUP($A13,'QMS Data'!$A:$BD,MATCH(H$1,'QMS Data'!$1:$1,0),FALSE),"") -> Silvia_ANaguib | I13: =IFERROR(VLOOKUP($A13,'QMS Data'!$A:$BD,MATCH(I$1,'QMS Data'!$1:$1,0),FALSE),"") -> 12 | ... S13: =IFERROR(VLOOKUP($A13,'QMS Data'!$A:$BD,MATCH(S$1,'QMS Data'!$1:$1,0),FALSE),"") -> 1 | T13: =IFERROR(I13-B13,"") -> 3 | U13: =IF(B13<>"",IF(B13>22,"W4",IF(B13>16,"W3",IF(B13>9,"W2",IF(B13>0,"W1",0)))),"") -> W1 | V13: =IFERROR(VLOOKUP('Required Data'!$H13,Evaluators!A:B,2,FALSE),"") -> Quality | W13: =IF(I13<>"",IF(I13>22,"W4",IF(I13>15,"W3",IF(I13>8,"W2",IF(I13>1,"W1",IF(I13=1,"W4",""))))),"") -> W2 | X13: =IFERROR(VLOOKUP(G13,'Active List'!B:D,2,FALSE),"") -> omnia_ahelmy | Y13: =IFERROR(SUM('Required Data'!$L13+'Required Data'!$N13+'Required Data'!$P13),"") -> 0 | Z13: =IFERROR(IF(HOUR(E13)<8,"Overnight",IF(HOUR(E13)<12,"Mornning",IF(HOUR(E13)<16,"Between",IF(HOUR(E13)<20,"Half Night","Night")))),"") -> Overnight | AA13: =IFERROR(DATE(Table1[[#This Row],[Call Year]],Table1[[#This Row],[Call Month]],Table1[[#This Row],[Call day]]),"") -> 46182 | AB13: =TEXT(Table1[[#This Row],[Call date]],"DDDD") -> Tuesday | AC13: =IFERROR(IF(Table1[[#This Row],[Call date]]-VLOOKUP(Table1[[#This Row],[Agent ID]],'Active List'!B:E,4,FALSE)>60,"old",IF(Table1[[#This Row],[Call date]]-VLOOKUP(Table1[[#This Row],[Agent ID]],'Active List'!B:E,4,FALSE)>30,"Bucket 2",IF(Table1[[#This Row],[Call date]]-VLOOKUP(Table1[[#This Row],[Agent ID]],'Active List'!B:E,4,FALSE)>0,"Bucket 1",""))),"") -> old | AD13: =IFERROR(HOUR(Table1[[#This Row],[Time]]),"") -> 3 | AE13: =IFERROR(VLOOKUP(J13,DV!A:B,2,FALSE),J13) -> Agent Level
... A341: =IF('QMS Data'!A341<>"",'QMS Data'!A341,"") | B341: =IFERROR(VLOOKUP($A341,'QMS Data'!$A:$BD,MATCH(B$1,'QMS Data'!$1:$1,0),FALSE),"") | C341: =IFERROR(VLOOKUP($A341,'QMS Data'!$A:$BD,MATCH(C$1,'QMS Data'!$1:$1,0),FALSE),"") | D341: =IFERROR(VLOOKUP($A341,'QMS Data'!$A:$BD,MATCH(D$1,'QMS Data'!$1:$1,0),FALSE),"") | E341: =IFERROR(VLOOKUP($A341,'QMS Data'!$A:$BD,MATCH(E$1,'QMS Data'!$1:$1,0),FALSE),"") | F341: =IFERROR(VLOOKUP($A341,'QMS Data'!$A:$BD,MATCH(F$1,'QMS Data'!$1:$1,0),FALSE),"") | G341: =IFERROR(VLOOKUP($A341,'QMS Data'!$A:$BD,MATCH(G$1,'QMS Data'!$1:$1,0),FALSE),"") | H341: =IFERROR(VLOOKUP($A341,'QMS Data'!$A:$BD,MATCH(H$1,'QMS Data'!$1:$1,0),FALSE),"") | I341: =IFERROR(VLOOKUP($A341,'QMS Data'!$A:$BD,MATCH(I$1,'QMS Data'!$1:$1,0),FALSE),"") | ... S341: =IFERROR(VLOOKUP($A341,'QMS Data'!$A:$BD,MATCH(S$1,'QMS Data'!$1:$1,0),FALSE),"") | T341: =IFERROR(I341-B341,"") | U341: =IF(B341<>"",IF(B341>22,"W4",IF(B341>16,"W3",IF(B341>9,"W2",IF(B341>0,"W1",0)))),"") | V341: =IFERROR(VLOOKUP('Required Data'!$H341,Evaluators!A:B,2,FALSE),"") | W341: =IF(I341<>"",IF(I341>22,"W4",IF(I341>15,"W3",IF(I341>8,"W2",IF(I341>1,"W1",IF(I341=1,"W4",""))))),"") | X341: =IFERROR(VLOOKUP(G341,'Active List'!B:D,2,FALSE),"") | Y341: =IFERROR(SUM('Required Data'!$L341+'Required Data'!$N341+'Required Data'!$P341),"") | Z341: =IFERROR(IF(HOUR(E341)<8,"Overnight",IF(HOUR(E341)<12,"Mornning",IF(HOUR(E341)<16,"Between",IF(HOUR(E341)<20,"Half Night","Night")))),"") | AA341: =IFERROR(DATE(Table1[[#This Row],[Call Year]],Table1[[#This Row],[Call Month]],Table1[[#This Row],[Call day]]),"") | AB341: =TEXT(Table1[[#This Row],[Call date]],"DDDD") | AC341: =IFERROR(IF(Table1[[#This Row],[Call date]]-VLOOKUP(Table1[[#This Row],[Agent ID]],'Active List'!B:E,4,FALSE)>60,"old",IF(Table1[[#This Row],[Call date]]-VLOOKUP(Table1[[#This Row],[Agent ID]],'Active List'!B:E,4,FALSE)>30,"Bucket 2",IF(Table1[[#This Row],[Call date]]-VLOOKUP(Table1[[#This Row],[Agent ID]],'Active List'!B:E,4,FALSE)>0,"Bucket 1",""))),"") | AD341: =IFERROR(HOUR(Table1[[#This Row],[Time]]),"") | AE341: =IFERROR(VLOOKUP(J341,DV!A:B,2,FALSE),J341)

Sheet Figures
B10: Queue | C10: Agent Level
C11: AL Target | D11: AL Achieved | E11: CC% | F11: EUC% | G11: BC% | H11: NC%
B12: Tatweer Misr | C12: 100 | D12: =COUNTIFS(Queue,B12,TargeType,$C$10) -> 11 | E12: =AVERAGEIFS(Compliance_Critical_Percentage,Queue,B12,TargeType,$C$10) -> 1 | F12: =AVERAGEIFS(End_User_Crirical_Percentage,Queue,B12,TargeType,$C$10) -> 1 | G12: =AVERAGEIFS(Busniss_Critical_Percentage,Queue,B12,TargeType,$C$10) -> 1 | H12: =AVERAGEIFS(Non_Critical_Percentage,Queue,B12,TargeType,$C$10) -> 0.97727273
B13: Proper T | C13: 100 | D13: =COUNTIFS(Queue,B13,TargeType,$C$10) -> 14 | E13: =AVERAGEIFS(Compliance_Critical_Percentage,Queue,B13,TargeType,$C$10) -> 1 | F13: =AVERAGEIFS(End_User_Crirical_Percentage,Queue,B13,TargeType,$C$10) -> 1 | G13: =AVERAGEIFS(Busniss_Critical_Percentage,Queue,B13,TargeType,$C$10) -> 0.92857143 | H13: =AVERAGEIFS(Non_Critical_Percentage,Queue,B13,TargeType,$C$10) -> 0.98214286
B14: Tatweer Misr OB Survey | C14: 0 | D14: =COUNTIFS(Queue,B14,TargeType,$C$10) -> 0 | E14: =AVERAGEIFS(Compliance_Critical_Percentage,Queue,B14,TargeType,$C$10) -> #DIV/0! | F14: =AVERAGEIFS(End_User_Crirical_Percentage,Queue,B14,TargeType,$C$10) -> #DIV/0! | G14: =AVERAGEIFS(Busniss_Critical_Percentage,Queue,B14,TargeType,$C$10) -> #DIV/0! | H14: =AVERAGEIFS(Non_Critical_Percentage,Queue,B14,TargeType,$C$10) -> #DIV/0!
B16: Tatweer Misr | C16: Agent Level
B17: TL Figures | C17: CC% | D17: EUC% | E17: BC% | F17: NC%
B18: Omnia_AHelmy | C18: =AVERAGEIFS(Compliance_Critical_Percentage,Queue,$B$16,TL,$B18,TargeType,C$16) -> 1 | D18: =AVERAGEIFS(End_User_Crirical_Percentage,Queue,$B$16,TL,$B18,TargeType,C$16) -> 1 | E18: =AVERAGEIFS(Busniss_Critical_Percentage,Queue,$B$16,TL,$B18,TargeType,C$16) -> 1 | F18: =AVERAGEIFS(Non_Critical_Percentage,Queue,$B$16,TL,$B18,TargeType,C$16) -> 0.95833333
B19: Mahmoud_HHamed | C19: =AVERAGEIFS(Compliance_Critical_Percentage,Queue,$B$16,TL,$B19,TargeType,C$16) -> 1 | D19: =AVERAGEIFS(End_User_Crirical_Percentage,Queue,$B$16,TL,$B19,TargeType,C$16) -> 1 | E19: =AVERAGEIFS(Busniss_Critical_Percentage,Queue,$B$16,TL,$B19,TargeType,C$16) -> 1 | F19: =AVERAGEIFS(Non_Critical_Percentage,Queue,$B$16,TL,$B19,TargeType,C$16) -> 0.975
B23: Proper T | C23: Agent Level | D23: Manual Agent Level | E23: Manual Agent Level | F23: Manual Agent Level
B24: TL Figures | C24: CC% | D24: EUC% | E24: BC% | F24: NC%
B25: Omnia_AHelmy | C25: =AVERAGEIFS(Compliance_Critical_Percentage,Queue,$B$23,TL,$B25,TargeType,C$23) -> 1 | D25: =AVERAGEIFS(End_User_Crirical_Percentage,Queue,$B$23,TL,$B25,TargeType,C$23) -> 1 | E25: =AVERAGEIFS(Busniss_Critical_Percentage,Queue,$B$23,TL,$B25,TargeType,C$23) -> 0.75 | F25: =AVERAGEIFS(Non_Critical_Percentage,Queue,$B$23,TL,$B25,TargeType,C$23) -> 1
B26: Mahmoud_HHamed | C26: =AVERAGEIFS(Compliance_Critical_Percentage,Queue,$B$23,TL,$B26,TargeType,C$23) -> 1 | D26: =AVERAGEIFS(End_User_Crirical_Percentage,Queue,$B$23,TL,$B26,TargeType,C$23) -> 1 | E26: =AVERAGEIFS(Busniss_Critical_Percentage,Queue,$B$23,TL,$B26,TargeType,C$23) -> 1 | F26: =AVERAGEIFS(Non_Critical_Percentage,Queue,$B$23,TL,$B26,TargeType,C$23) -> 0.98214286
B30: Tatweer Misr OB Survey | C30: Agent Level
B31: TL Figures | C31: CC% | D31: EUC% | E31: BC% | F31: NC%
B32: Omnia_AHelmy | C32: =AVERAGEIFS(Compliance_Critical_Percentage,Queue,$B$30,TL,$B32,TargeType,C$30) -> #DIV/0! | D32: =AVERAGEIFS(End_User_Crirical_Percentage,Queue,$B$30,TL,$B32,TargeType,C$30) -> #DIV/0! | E32: =AVERAGEIFS(Busniss_Critical_Percentage,Queue,$B$30,TL,$B32,TargeType,C$30) -> #DIV/0! | F32: =AVERAGEIFS(Non_Critical_Percentage,Queue,$B$30,TL,$B32,TargeType,C$30) -> #DIV/0!
B33: Mahmoud_HHamed | C33: =AVERAGEIFS(Compliance_Critical_Percentage,Queue,$B$30,TL,$B33,TargeType,C$30) -> #DIV/0! | D33: =AVERAGEIFS(End_User_Crirical_Percentage,Queue,$B$30,TL,$B33,TargeType,C$30) -> #DIV/0! | E33: =AVERAGEIFS(Busniss_Critical_Percentage,Queue,$B$30,TL,$B33,TargeType,C$30) -> #DIV/0! | F33: =AVERAGEIFS(Non_Critical_Percentage,Queue,$B$30,TL,$B33,TargeType,C$30) -> #DIV/0!
B38: Weekly View | C38: Agent Level | D38: Manual Program Level | E38: Manual Program Level | F38: Manual Program Level
B39: Tatweer Misr | C39: CC% | D39: EUC% | E39: BC% | F39: NC%
B40: W1 | C40: =IFERROR(AVERAGEIFS(Compliance_Critical_Percentage,Queue,$B$39,TargeType,$C$46,CallWeek,B40),"") -> 1 | D40: =IFERROR(AVERAGEIFS(End_User_Crirical_Percentage,Queue,$B$39,TargeType,$C$46,CallWeek,B40),"") -> 1 | E40: =IFERROR(AVERAGEIFS(Busniss_Critical_Percentage,Queue,$B$39,TargeType,$C$46,CallWeek,B40),"") -> 1 | F40: =IFERROR(AVERAGEIFS(Non_Critical_Percentage,Queue,$B$39,TargeType,$C$46,CallWeek,B40),"") -> 1
B41: W2 | C41: =IFERROR(AVERAGEIFS(Compliance_Critical_Percentage,Queue,$B$39,TargeType,$C$46,CallWeek,B41),"") -> 1 | D41: =IFERROR(AVERAGEIFS(End_User_Crirical_Percentage,Queue,$B$39,TargeType,$C$46,CallWeek,B41),"") -> 1 | E41: =IFERROR(AVERAGEIFS(Busniss_Critical_Percentage,Queue,$B$39,TargeType,$C$46,CallWeek,B41),"") -> 1 | F41: =IFERROR(AVERAGEIFS(Non_Critical_Percentage,Queue,$B$39,TargeType,$C$46,CallWeek,B41),"") -> 0.97222222
B42: W3 | C42: =IFERROR(AVERAGEIFS(Compliance_Critical_Percentage,Queue,$B$39,TargeType,$C$46,CallWeek,B42),"") -> 1 | D42: =IFERROR(AVERAGEIFS(End_User_Crirical_Percentage,Queue,$B$39,TargeType,$C$46,CallWeek,B42),"") -> 1 | E42: =IFERROR(AVERAGEIFS(Busniss_Critical_Percentage,Queue,$B$39,TargeType,$C$46,CallWeek,B42),"") -> 1 | F42: =IFERROR(AVERAGEIFS(Non_Critical_Percentage,Queue,$B$39,TargeType,$C$46,CallWeek,B42),"") -> 1
B43: W4 | C43: =IFERROR(AVERAGEIFS(Compliance_Critical_Percentage,Queue,$B$39,TargeType,$C$46,CallWeek,B43),"") | D43: =IFERROR(AVERAGEIFS(End_User_Crirical_Percentage,Queue,$B$39,TargeType,$C$46,CallWeek,B43),"") | E43: =IFERROR(AVERAGEIFS(Busniss_Critical_Percentage,Queue,$B$39,TargeType,$C$46,CallWeek,B43),"") | F43: =IFERROR(AVERAGEIFS(Non_Critical_Percentage,Queue,$B$39,TargeType,$C$46,CallWeek,B43),"")
B46: Weekly View | C46: Agent Level | D46: Manual Program Level | E46: Manual Program Level | F46: Manual Program Level
B47: Proper T | C47: CC% | D47: EUC% | E47: BC% | F47: NC%
B48: W1 | C48: =IFERROR(AVERAGEIFS(Compliance_Critical_Percentage,Queue,$B$47,TargeType,$C$46,CallWeek,B48),"") -> 1 | D48: =IFERROR(AVERAGEIFS(End_User_Crirical_Percentage,Queue,$B$47,TargeType,$C$46,CallWeek,B48),"") -> 1 | E48: =IFERROR(AVERAGEIFS(Busniss_Critical_Percentage,Queue,$B$47,TargeType,$C$46,CallWeek,B48),"") -> 0.5 | F48: =IFERROR(AVERAGEIFS(Non_Critical_Percentage,Queue,$B$47,TargeType,$C$46,CallWeek,B48),"") -> 1
B49: W2 | C49: =IFERROR(AVERAGEIFS(Compliance_Critical_Percentage,Queue,$B$47,TargeType,$C$46,CallWeek,B49),"") -> 1 | D49: =IFERROR(AVERAGEIFS(End_User_Crirical_Percentage,Queue,$B$47,TargeType,$C$46,CallWeek,B49),"") -> 1 | E49: =IFERROR(AVERAGEIFS(Busniss_Critical_Percentage,Queue,$B$47,TargeType,$C$46,CallWeek,B49),"") -> 1 | F49: =IFERROR(AVERAGEIFS(Non_Critical_Percentage,Queue,$B$47,TargeType,$C$46,CallWeek,B49),"") -> 1
B50: W3 | C50: =IFERROR(AVERAGEIFS(Compliance_Critical_Percentage,Queue,$B$47,TargeType,$C$46,CallWeek,B50),"") -> 1 | D50: =IFERROR(AVERAGEIFS(End_User_Crirical_Percentage,Queue,$B$47,TargeType,$C$46,CallWeek,B50),"") -> 1 | E50: =IFERROR(AVERAGEIFS(Busniss_Critical_Percentage,Queue,$B$47,TargeType,$C$46,CallWeek,B50),"") -> 1 | F50: =IFERROR(AVERAGEIFS(Non_Critical_Percentage,Queue,$B$47,TargeType,$C$46,CallWeek,B50),"") -> 0.9375
B51: W4 | C51: =IFERROR(AVERAGEIFS(Compliance_Critical_Percentage,Queue,$B$47,TargeType,$C$46,CallWeek,B51),"") | D51: =IFERROR(AVERAGEIFS(End_User_Crirical_Percentage,Queue,$B$47,TargeType,$C$46,CallWeek,B51),"") | E51: =IFERROR(AVERAGEIFS(Busniss_Critical_Percentage,Queue,$B$47,TargeType,$C$46,CallWeek,B51),"") | F51: =IFERROR(AVERAGEIFS(Non_Critical_Percentage,Queue,$B$47,TargeType,$C$46,CallWeek,B51),"")
B56: Tatweer Misr OB Survey | C56: Agent Level | D56: Manual Program Level | E56: Manual Program Level | F56: Manual Program Level
B57: Tatweer Misr | C57: CC% | D57: EUC% | E57: BC% | F57: NC%
B58: W1 | C58: =IFERROR(AVERAGEIFS(End_User_Crirical_Percentage,Queue,$B$56,TargeType,$C$56,CallWeek,A58),"") | D58: =IFERROR(AVERAGEIFS(End_User_Crirical_Percentage,Queue,$B$56,TargeType,$C$56,CallWeek,B58),"") | E58: =IFERROR(AVERAGEIFS(Busniss_Critical_Percentage,Queue,$B$56,TargeType,$C$56,CallWeek,B58),"") | F58: =IFERROR(AVERAGEIFS(Non_Critical_Percentage,Queue,$B$56,TargeType,$C$56,CallWeek,B58),"")
B59: W2 | C59: =IFERROR(AVERAGEIFS(End_User_Crirical_Percentage,Queue,$B$56,TargeType,$C$56,CallWeek,A59),"") | D59: =IFERROR(AVERAGEIFS(End_User_Crirical_Percentage,Queue,$B$56,TargeType,$C$56,CallWeek,B59),"") | E59: =IFERROR(AVERAGEIFS(Busniss_Critical_Percentage,Queue,$B$56,TargeType,$C$56,CallWeek,B59),"") | F59: =IFERROR(AVERAGEIFS(Non_Critical_Percentage,Queue,$B$56,TargeType,$C$56,CallWeek,B59),"")
B60: W3 | C60: =IFERROR(AVERAGEIFS(End_User_Crirical_Percentage,Queue,$B$56,TargeType,$C$56,CallWeek,A60),"") | D60: =IFERROR(AVERAGEIFS(End_User_Crirical_Percentage,Queue,$B$56,TargeType,$C$56,CallWeek,B60),"") | E60: =IFERROR(AVERAGEIFS(Busniss_Critical_Percentage,Queue,$B$56,TargeType,$C$56,CallWeek,B60),"") | F60: =IFERROR(AVERAGEIFS(Non_Critical_Percentage,Queue,$B$56,TargeType,$C$56,CallWeek,B60),"")
B61: W4 | C61: =IFERROR(AVERAGEIFS(End_User_Crirical_Percentage,Queue,$B$56,TargeType,$C$56,CallWeek,A61),"") | D61: =IFERROR(AVERAGEIFS(End_User_Crirical_Percentage,Queue,$B$56,TargeType,$C$56,CallWeek,B61),"") | E61: =IFERROR(AVERAGEIFS(Busniss_Critical_Percentage,Queue,$B$56,TargeType,$C$56,CallWeek,B61),"") | F61: =IFERROR(AVERAGEIFS(Non_Critical_Percentage,Queue,$B$56,TargeType,$C$56,CallWeek,B61),"")
B75: Number of Mointored Calls by QAE | C75: Number of Critical done by QA | D75: % Critical by QA | E75: Number of Non Critical done by QA | F75: % Non Critical by QA | G75: Number of Mointored Calls by TL | H75: Number Critical done by TL | I75: % Critical by TL | J75: Number of Non Critical done by TL | K75: % Non Critical by TL | L75: % Variance in the project in C | M75: % Variance in the project in NC
A76: Tatweer Misr | B76: =COUNTIFS(DEP,"Quality",Queue,A76) -> 10 | C76: =SUMIFS(Compliance_Critical,DEP,"Quality",Queue,A76)+SUMIFS(End_User_Crirical,DEP,"Quality",Queue,A76)+SUMIFS(Busniss_Critical,DEP,"Quality",Queue,A76) -> 0 | D76: =C76/B76 -> 0 | E76: =SUMIFS(Non_Critical,DEP,"Quality",Queue,A76) -> 2 | F76: =E76/(B76*8) -> 0.025 | G76: =COUNTIFS(DEP,"Operation",Queue,A76) -> 1 | H76: =SUMIFS(Compliance_Critical,DEP,"Operation",Queue,A76)+SUMIFS(End_User_Crirical,DEP,"Operation",Queue,A76)+SUMIFS(Busniss_Critical,DEP,"Operation",Queue,A76) -> 0 | I76: =H76/G76 -> 0 | J76: =SUMIFS(Non_Critical,DEP,"Operation",Queue,A76) -> 0 | K76: =J76/(G76*8) -> 0 | L76: =D76-I76 -> 0 | M76: =F76-K76 -> 0.025
A77: Proper T | B77: =COUNTIFS(DEP,"Quality",Queue,A77) -> 14 | C77: =SUMIFS(Compliance_Critical,DEP,"Quality",Queue,A77)+SUMIFS(End_User_Crirical,DEP,"Quality",Queue,A77)+SUMIFS(Busniss_Critical,DEP,"Quality",Queue,A77) -> 1 | D77: =C77/B77 -> 0.071428571 | E77: =SUMIFS(Non_Critical,DEP,"Quality",Queue,A77) -> 2 | F77: =E77/(B77*8) -> 0.017857143 | G77: =COUNTIFS(DEP,"Operation",Queue,A77) -> 0 | H77: =SUMIFS(Compliance_Critical,DEP,"Operation",Queue,A77)+SUMIFS(End_User_Crirical,DEP,"Operation",Queue,A77)+SUMIFS(Busniss_Critical,DEP,"Operation",Queue,A77) -> 0 | I77: =H77/G77 -> #DIV/0! | J77: =SUMIFS(Non_Critical,DEP,"Operation",Queue,A77) -> 0 | K77: =J77/(G77*8) -> #DIV/0! | L77: =D77-I77 -> #DIV/0! | M77: =F77-K77 -> #DIV/0!
A78: Tatweer Misr OB Survey | B78: =COUNTIFS(DEP,"Quality",Queue,A78) -> 0 | C78: =SUMIFS(Compliance_Critical,DEP,"Quality",Queue,A78)+SUMIFS(End_User_Crirical,DEP,"Quality",Queue,A78)+SUMIFS(Busniss_Critical,DEP,"Quality",Queue,A78) -> 0 | D78: =C78/B78 -> #DIV/0! | E78: =SUMIFS(Non_Critical,DEP,"Quality",Queue,A78) -> 0 | F78: =E78/(B78*8) -> #DIV/0! | G78: =COUNTIFS(DEP,"Operation",Queue,A78) -> 0 | H78: =SUMIFS(Compliance_Critical,DEP,"Operation",Queue,A78)+SUMIFS(End_User_Crirical,DEP,"Operation",Queue,A78)+SUMIFS(Busniss_Critical,DEP,"Operation",Queue,A78) -> 0 | I78: =H78/G78 -> #DIV/0! | J78: =SUMIFS(Non_Critical,DEP,"Operation",Queue,A78) -> 0 | K78: =J78/(G78*8) -> #DIV/0! | L78: =D78-I78 -> #DIV/0! | M78: =F78-K78 -> #DIV/0!

Sheet QMS Data
A1: Call Id | B1: Call Date | C1: Call day | D1: Call Month | E1: Call Year | F1: Time | G1: Duration | H1: Caller ID | I1: Called ID | J1: Queue | K1: Agent ID | L1: Agent Name | M1: Agent Status | N1: TeamLeader | O1: Evaluation Score | P1: Evaluator Name | Q1: Evaluation Date | R1: Evaluation day | S1: Evaluation Month | T1: Evaluation Year | U1: Result | V1: TargeType | W1: AgentStatus | X1: TeamLeader | Y1: Busniss Critical | Z1: Busniss Critical_Percentage | AA1: Compliance Critical | AB1: Compliance Critical_Percentage | AC1: End-User Crirical | AD1: End-User Crirical_Percentage | AE1: Non Critical | AF1: Non Critical_Percentage | AG1: Customer Name | AH1: Customer Contact/Phone | AI1: FCR | AJ1: Noise background | AK1: SBS Findings | AL1: SBS Comment | AM1: FCR Reason | AN1: End User Feedback | AO1: Negative Feedback Source | AP1: Reason FCR (NO) | AQ1: Customer Feedback | AR1: Customer Feedback Comment | AS1: FCR Text | AT1: Escalation | AU1: Coaching Reference | AV1: Reason of Negative Feedback | AW1: WOW Call | AX1: Call Type | AY1: Ops | AZ1: HR | BA1: IT | BB1: WF | BC1: Training
A2: 514010093 | B2: 46028 | C2: 1 | D2: 6 | E2: 2026 | F2: 0.53327546 | G2: 0 | J2: Tatweer Misr | K2: 32462 | L2: Shahd Ashraf Muhamed Saber | M2: Old | P2: Omnia_A Helmy | Q2: 46174.789 | R2: 1 | S2: 6 | T2: 2026 | U2: Pass | V2: Manual Agent Level | W2: Old | Y2: 0 | Z2: 1 | AA2: 0 | AB2: 1 | AC2: 0 | AD2: 1 | AE2: 0 | AF2: 1 | AI2: No | AJ2: No | AM2: RCC | AP2: Process | AT2: Valid | AX2: Technical client Relation
A3: 515267273 | B3: 14/06/2026 | C3: 14 | D3: 6 | E3: 2026 | F3: 0.59328704 | G3: 0.0015393519 | I3: 61134 | J3: Tatweer Misr | K3: 32755 | L3: Hatem Shady Farouk | M3: Old | P3: Silvia_ANaguib | Q3: 46188.616 | R3: 15 | S3: 6 | T3: 2026 | U3: Pass | V3: Agent Level | W3: Old | Y3: 0 | Z3: 1 | AA3: 0 | AB3: 1 | AC3: 0 | AD3: 1 | AE3: 0 | AF3: 1 | AI3: No | AJ3: No | AT3: Valid | AX3: Technical client Relation | BC3: No
A4: 515278813 | B4: 14/06/2026 | C4: 14 | D4: 6 | E4: 2026 | F4: 0.63731481 | G4: 0.0029861111 | I4: 61134 | J4: Tatweer Misr | K4: 32755 | L4: Hatem Shady Farouk | M4: Old | P4: Silvia_ANaguib | Q4: 46188.711 | R4: 15 | S4: 6 | T4: 2026 | U4: Pass | V4: Agent Level | W4: Old | Y4: 0 | Z4: 1 | AA4: 0 | AB4: 1 | AC4: 0 | AD4: 1 | AE4: 0 | AF4: 1 | AI4: No | AJ4: No | AT4: Valid | AX4: Technical client Relation | BC4: No
A5: 515580495 | B5: 17/06/2026 | C5: 17 | D5: 6 | E5: 2026 | F5: 0.43489583 | G5: 0.0030439815 | I5: 61142 | J5: Tatweer Misr | K5: 32767 | L5: Marwan Walid Reda | P5: Silvia_ANaguib | Q5: 46191.626 | R5: 18 | S5: 6 | T5: 2026 | U5: Pass | V5: Agent Level | Y5: 0 | Z5: 1 | AA5: 0 | AB5: 1 | AC5: 0 | AD5: 1 | AE5: 0 | AF5: 1 | AI5: No | AJ5: No | AT5: Valid | AX5: Client Relation | BC5: Yes
A6: 515013664 | B6: 46332 | C6: 11 | D6: 6 | E6: 2026 | F6: 0.62005787 | G6: 0.0048842593 | I6: 61132 | J6: Tatweer Misr | K6: 33277 | L6: Karim Magdy Hassan | M6: Old | P6: Silvia_ANaguib | Q6: 46185.766 | R6: 12 | S6: 6 | T6: 2026 | U6: Pass | V6: Agent Level | W6: Old | Y6: 0 | Z6: 1 | AA6: 0 | AB6: 1 | AC6: 0 | AD6: 1 | AE6: 1 | AF6: 0.875 | AI6: No | AJ6: Yes | AT6: Valid | AX6: Client Relation | BC6: No
A7: 515288065 | B7: 14/06/2026 | C7: 14 | D7: 6 | E7: 2026 | F7: 0.67179398 | G7: 0.001875 | I7: 61136 | J7: Tatweer Misr | K7: 33271 | L7: Mina Mahrous Samuel | M7: Old | P7: Silvia_ANaguib | Q7: 46188.741 | R7: 15 | S7: 6 | T7: 2026 | U7: Pass | V7: Agent Level | W7: Old | Y7: 0 | Z7: 1 | AA7: 0 | AB7: 1 | AC7: 0 | AD7: 1 | AE7: 0 | AF7: 1 | AI7: No | AJ7: No | AT7: Valid | AX7: Client Relation | BC7: No
A8: 515308820 | B8: 14/06/2026 | C8: 14 | D8: 6 | E8: 2026 | F8: 0.78024306 | G8: 0.0011805556 | I8: 61136 | J8: Tatweer Misr | K8: 33271 | L8: Mina Mahrous Samuel | M8: Old | P8: Silvia_ANaguib | Q8: 46188.618 | R8: 15 | S8: 6 | T8: 2026 | U8: Pass | V8: Agent Level | W8: Old | Y8: 0 | Z8: 1 | AA8: 0 | AB8: 1 | AC8: 0 | AD8: 1 | AE8: 0 | AF8: 1 | AI8: Yes | AJ8: No | AT8: NA | AX8: General Inquiry | BC8: No
A9: 514867960 | B9: 46301 | C9: 10 | D9: 6 | E9: 2026 | F9: 0.45792824 | G9: 0.0014583333 | I9: 61140 | J9: Tatweer Misr | K9: 31924 | L9: Nayera Mohamed Most | M9: Old | P9: Silvia_ANaguib | Q9: 46185.706 | R9: 12 | S9: 6 | T9: 2026 | U9: Pass | V9: Agent Level | W9: Old | Y9: 0 | Z9: 1 | AA9: 0 | AB9: 1 | AC9: 0 | AD9: 1 | AE9: 1 | AF9: 0.875 | AI9: No | AJ9: No | AT9: Valid | AX9: Client Relation | BC9: No
A10: 514861967 | B10: 46301 | C10: 10 | D10: 6 | E10: 2026 | F10: 0.42003472 | G10: 0.0031481481 | I10: 61124 | J10: Tatweer Misr | K10: 32962 | L10: Salma mohamed aly m | M10: Old | P10: Silvia_ANaguib | Q10: 46185.676 | R10: 12 | S10: 6 | T10: 2026 | U10: Pass | V10: Agent Level | W10: Old | Y10: 0 | Z10: 1 | AA10: 0 | AB10: 1 | AC10: 0 | AD10: 1 | AE10: 0 | AF10: 1 | AI10: No | AJ10: No | AT10: Valid | AX10: Technical client Relation | BC10: No
A11: 514871947 | B11: 46301 | C11: 10 | D11: 6 | E11: 2026 | F11: 0.4780787 | G11: 0.0021643519 | I11: 60510 | J11: Tatweer Misr | K11: 32462 | L11: Shahd Ashraf Muhame | M11: Old | P11: Silvia_ANaguib | Q11: 46185.702 | R11: 12 | S11: 6 | T11: 2026 | U11: Pass | V11: Agent Level | W11: Old | Y11: 0 | Z11: 1 | AA11: 0 | AB11: 1 | AC11: 0 | AD11: 1 | AE11: 0 | AF11: 1 | AI11: No | AJ11: No | AT11: Valid | AX11: Collection and Credit Control | BC11: No
A12: 514904778 | B12: 46301 | C12: 10 | D12: 6 | E12: 2026 | F12: 0.63818287 | G12: 0.0015625 | I12: 61141 | J12: Tatweer Misr | K12: 33270 | L12: Yasmeen Mohammed Ma | M12: Old | P12: Silvia_ANaguib | Q12: 46185.674 | R12: 12 | S12: 6 | T12: 2026 | U12: Pass | V12: Agent Level | W12: Old | Y12: 0 | Z12: 1 | AA12: 0 | AB12: 1 | AC12: 0 | AD12: 1 | AE12: 0 | AF12: 1 | AI12: No | AJ12: No | AT12: Valid | AX12: Resale | BC12: No
A13: 514741104 | B13: 46271 | C13: 9 | D13: 6 | E13: 2026 | F13: 0.13244213 | G13: 0.0015740741 | I13: 60505 | J13: Proper T | K13: 39025 | L13: Abdelrahman Sayed M | M13: Old | P13: Silvia_ANaguib | Q13: 46185.744 | R13: 12 | S13: 6 | T13: 2026 | U13: Pass | V13: Agent Level | W13: Old | Y13: 0 | Z13: 1 | AA13: 0 | AB13: 1 | AC13: 0 | AD13: 1 | AE13: 0 | AF13: 1 | AI13: No | AJ13: No | AT13: Valid | BC13: No
A14: 514842138 | B14: 46271 | C14: 9 | D14: 6 | E14: 2026 | F14: 0.94068287 | G14: 0.0045601852 | I14: 61133 | J14: Proper T | K14: 32760 | L14: Hussien Ahmed Moham | M14: Old | P14: Silvia_ANaguib | Q14: 46185.75 | R14: 12 | S14: 6 | T14: 2026 | U14: Fail | V14: Agent Level | W14: Old | Y14: 1 | Z14: 0 | AA14: 0 | AB14: 1 | AC14: 0 | AD14: 1 | AE14: 0 | AF14: 1 | AI14: No | AJ14: No | AT14: NA | BC14: No
A15: 514881390 | B15: 46301 | C15: 10 | D15: 6 | E15: 2026 | F15: 0.52431713 | G15: 0.0042824074 | I15: 61125 | J15: Proper T | K15: 32764 | L15: Aya Tullah Abdelkha | M15: Old | P15: Silvia_ANaguib | Q15: 46185.672 | R15: 12 | S15: 6 | T15: 2026 | U15: Pass | V15: Agent Level | W15: Old | Y15: 0 | Z15: 1 | AA15: 0 | AB15: 1 | AC15: 0 | AD15: 1 | AE15: 0 | AF15: 1 | AI15: No | AJ15: Yes | AT15: Valid | BC15: No
A16: 514888084 | B16: 46301 | C16: 10 | D16: 6 | E16: 2026 | F16: 0.5596875 | G16: 0.0013425926 | I16: 61137 | J16: Proper T | K16: 33279 | L16: Clair Maher Nageh | M16: Old | P16: Silvia_ANaguib | Q16: 46185.637 | R16: 12 | S16: 6 | T16: 2026 | U16: Pass | V16: Agent Level | W16: Old | Y16: 0 | Z16: 1 | AA16: 0 | AB16: 1 | AC16: 0 | AD16: 1 | AE16: 0 | AF16: 1 | AI16: No | AJ16: No | AT16: Valid | AX16: Electric Work | BC16: No
A17: 514970434 | B17: 46332 | C17: 11 | D17: 6 | E17: 2026 | F17: 0.4028125 | G17: 0.002037037 | I17: 61140 | J17: Proper T | K17: 31924 | L17: Nayera Mohamed Most | M17: Old | P17: Silvia_ANaguib | Q17: 46185.567 | R17: 12 | S17: 6 | T17: 2026 | U17: Pass | V17: Agent Level | W17: Old | Y17: 0 | Z17: 1 | AA17: 0 | AB17: 1 | AC17: 0 | AD17: 1 | AE17: 0 | AF17: 1 | AI17: No | AJ17: No | AT17: Valid | BC17: No
A18: 515017500 | B18: 46332 | C18: 11 | D18: 6 | E18: 2026 | F18: 0.64017361 | G18: 0.0011226852 | I18: 61132 | J18: Proper T | K18: 33277 | L18: Karim Magdy Hassan | M18: Old | P18: Silvia_ANaguib | Q18: 46185.565 | R18: 12 | S18: 6 | T18: 2026 | U18: Pass | V18: Agent Level | W18: Old | Y18: 0 | Z18: 1 | AA18: 0 | AB18: 1 | AC18: 0 | AD18: 1 | AE18: 0 | AF18: 1 | AI18: Yes | AJ18: No | AQ18: Client refused to give the unit number | AT18: NA | AX18: Housekeeping Service | BC18: No
A19: 515094054 | B19: 46362 | C19: 12 | D19: 6 | E19: 2026 | F19: 0.60979167 | G19: 0.0016203704 | I19: 60504 | J19: Proper T | K19: 39024 | L19: Rawan Hussien Mosta | M19: Not Certified | P19: Silvia_ANaguib | Q19: 46188.63 | R19: 15 | S19: 6 | T19: 2026 | U19: Pass | V19: Agent Level | W19: Not Certified | Y19: 0 | Z19: 1 | AA19: 0 | AB19: 1 | AC19: 0 | AD19: 1 | AE19: 0 | AF19: 1 | AI19: No | AJ19: Yes | AT19: NA | AX19: Housekeeping Service | BC19: No
A20: 515306969 | B20: 14/06/2026 | C20: 14 | D20: 6 | E20: 2026 | F20: 0.76796296 | G20: 0.0011574074 | I20: 61136 | J20: Proper T | K20: 33271 | L20: Mina Mahrous Samuel | M20: Old | P20: Silvia_ANaguib | Q20: 46188.748 | R20: 15 | S20: 6 | T20: 2026 | U20: Pass | V20: Agent Level | W20: Old | Y20: 0 | Z20: 1 | AA20: 0 | AB20: 1 | AC20: 0 | AD20: 1 | AE20: 0 | AF20: 1 | AI20: Yes | AJ20: No | AT20: NA | AX20: Housekeeping Service | BC20: No
A21: 515310714 | B21: 14/06/2026 | C21: 14 | D21: 6 | E21: 2026 | F21: 0.79226852 | G21: 0.0013194444 | I21: 61136 | J21: Proper T | K21: 33271 | L21: Mina Mahrous Samuel | M21: Old | P21: Silvia_ANaguib | Q21: 46188.613 | R21: 15 | S21: 6 | T21: 2026 | U21: Pass | V21: Agent Level | W21: Old | Y21: 0 | Z21: 1 | AA21: 0 | AB21: 1 | AC21: 0 | AD21: 1 | AE21: 0 | AF21: 1 | AI21: Yes | AJ21: No | AT21: NA | AX21: Housekeeping Service | BC21: No
A22: 515321269 | B22: 14/06/2026 | C22: 14 | D22: 6 | E22: 2026 | F22: 0.89298611 | G22: 0.00091435185 | I22: 61141 | J22: Proper T | K22: 33270 | L22: Yasmeen Mohammed Ma | M22: Old | P22: Silvia_ANaguib | Q22: 46188.747 | R22: 15 | S22: 6 | T22: 2026 | U22: Pass | V22: Skipped Agent Level | W22: Old | Y22: 0 | Z22: 1 | AA22: 0 | AB22: 1 | AC22: 0 | AD22: 1 | AE22: 0 | AF22: 1 | AI22: Yes | AJ22: No | AT22: NA | AX22: Housekeeping Service | BC22: No
A23: 515577668 | B23: 17/06/2026 | C23: 17 | D23: 6 | E23: 2026 | F23: 0.41644676 | G23: 0.001712963 | I23: 61141 | J23: Proper T | K23: 33270 | L23: Yasmeen Mohammed Ma | M23: Old | P23: Silvia_ANaguib | Q23: 46191.536 | R23: 18 | S23: 6 | T23: 2026 | U23: Pass | V23: Agent Level | W23: Old | Y23: 0 | Z23: 1 | AA23: 0 | AB23: 1 | AC23: 0 | AD23: 1 | AE23: 1 | AF23: 0.875 | AI23: No | AJ23: No | AT23: Valid | AX23: Plumbing Work | BC23: No
A24: 515598361 | B24: 17/06/2026 | C24: 17 | D24: 6 | E24: 2026 | F24: 0.52797454 | G24: 0.0012962963 | I24: 61122 | J24: Proper T | K24: 32747 | L24: Ahmed Reda Ahmed A | M24: Old | P24: Silvia_ANaguib | Q24: 46191.535 | R24: 18 | S24: 6 | T24: 2026 | U24: Pass | V24: Agent Level | W24: Old | Y24: 0 | Z24: 1 | AA24: 0 | AB24: 1 | AC24: 0 | AD24: 1 | AE24: 1 | AF24: 0.875 | AI24: No | AJ24: No | AT24: Valid | AX24: Plumbing Work | BC24: No
A25: 515622525 | B25: 17/06/2026 | C25: 17 | D25: 6 | E25: 2026 | F25: 0.63759259 | G25: 0.0039814815 | I25: 61139 | J25: Proper T | K25: 32754 | L25: Aya Osama Sayed Hu | M25: Old | P25: Silvia_ANaguib | Q25: 46191.613 | R25: 18 | S25: 6 | T25: 2026 | U25: Pass | V25: Agent Level | W25: Old | Y25: 0 | Z25: 1 | AA25: 0 | AB25: 1 | AC25: 0 | AD25: 1 | AE25: 0 | AF25: 1 | AI25: No | AJ25: Yes | AT25: Valid | AX25: Housekeeping Service | BC25: No
A26: 515648478 | B26: 17/06/2026 | C26: 17 | D26: 6 | E26: 2026 | F26: 0.76298611 | G26: 0.0022453704 | I26: 61122 | J26: Proper T | K26: 32747 | L26: Ahmed Reda Ahmed A | M26: Old | P26: Silvia_ANaguib | Q26: 46191.616 | R26: 18 | S26: 6 | T26: 2026 | U26: Pass | V26: Agent Level | W26: Old | Y26: 0 | Z26: 1 | AA26: 0 | AB26: 1 | AC26: 0 | AD26: 1 | AE26: 0 | AF26: 1 | AI26: No | AJ26: No | AT26: Valid | AX26: Plumbing Work | BC26: No

Sheet Adherence Omnia
T1: Tatweer Misr- Omnia Adherence | V1: W1 | W1: W2 | X1: W3 | Y1: W4 | Z1: Total
B2: QMS Que Name | C2: Tatweer Misr | D2: Tatweer Misr | E2: Tatweer Misr | F2: Agent Status | J2: Target | N2: Adherence | T2: Target | V2: =J16 -> 10 | W2: =K16 -> 10 | X2: =L16 -> 0 | Y2: =M16 -> 0 | Z2: =SUM(V2:Y2) -> 20
B3: Login ID | C3: Name | D3: Skill | E3: WFH/WFS | F3: W1 | G3: W2 | H3: W3 | I3: W4 | J3: W1 | K3: W2 | L3: W3 | M3: W4 | N3: W1 | O3: W2 | P3: W3 | Q3: W4 | R3: Total Adherence | T3: Adherence | V3: =N16 -> 0 | W3: =O16 -> 0 | X3: =P16 -> 0 | Y3: =Q16 -> 1 | Z3: =SUM(V3:Y3) -> 1
B4: 32462 | C4: Shahd Ashraf Muhamed Saber | D4: IB | E4: WFS | F4: Old/(OP-QA) | G4: Old/(OP-QA) | J4: =IFERROR(VLOOKUP(F4,DV!$D:$E,2,FALSE),0) -> 1 | K4: =IFERROR(VLOOKUP(G4,DV!$D:$E,2,FALSE),0) -> 1 | L4: =IFERROR(VLOOKUP(H4,DV!$D:$E,2,FALSE),0) -> 0 | M4: =IFERROR(VLOOKUP(I4,DV!$D:$E,2,FALSE),0) -> 0 | N4: =COUNTIFS(Week,'Adherence Omnia'!N$3,Agent_ID,'Adherence Omnia'!$B4,TargeType,"Agent Level",Queue,$C$2,DEP,"Operation") -> 0 | O4: =COUNTIFS(Week,'Adherence Omnia'!O$3,Agent_ID,'Adherence Omnia'!$B4,TargeType,"Agent Level",Queue,$C$2,DEP,"Operation") -> 0 | P4: =COUNTIFS(Week,'Adherence Omnia'!P$3,Agent_ID,'Adherence Omnia'!$B4,TargeType,"Agent Level",Queue,$C$2,DEP,"Operation") -> 0 | Q4: =COUNTIFS(Week,'Adherence Omnia'!Q$3,Agent_ID,'Adherence Omnia'!$B4,TargeType,"Agent Level",Queue,$C$2,DEP,"Operation") -> 1 | R4: =SUM(N4:Q4)>=SUM(J4:M4) -> FALSE | S4: =IFERROR(SUM(#REF!)/SUM(#REF!),"") | T4: ACH | V4: =IF(V2<>0,V3/V2,"") -> 0 | W4: =IF(W2<>0,W3/W2,"") -> 0 | X4: =IF(X2<>0,X3/X2,"") | Y4: =IF(Y2<>0,Y3/Y2,"") | Z4: =IF(Z2<>0,Z3/Z2,"") -> 0.05
B5: 33271 | C5: Mina Mahrous Samuel Salib | D5: IB | E5: WFS | F5: Old/(OP-QA) | G5: Old/(OP-QA) | J5: =IFERROR(VLOOKUP(F5,DV!$D:$E,2,FALSE),0) -> 1 | K5: =IFERROR(VLOOKUP(G5,DV!$D:$E,2,FALSE),0) -> 1 | L5: =IFERROR(VLOOKUP(H5,DV!$D:$E,2,FALSE),0) -> 0 | M5: =IFERROR(VLOOKUP(I5,DV!$D:$E,2,FALSE),0) -> 0 | N5: =COUNTIFS(Week,'Adherence Omnia'!N$3,Agent_ID,'Adherence Omnia'!$B5,TargeType,"Agent Level",Queue,$C$2,DEP,"Operation") -> 0 | O5: =COUNTIFS(Week,'Adherence Omnia'!O$3,Agent_ID,'Adherence Omnia'!$B5,TargeType,"Agent Level",Queue,$C$2,DEP,"Operation") -> 0 | P5: =COUNTIFS(Week,'Adherence Omnia'!P$3,Agent_ID,'Adherence Omnia'!$B5,TargeType,"Agent Level",Queue,$C$2,DEP,"Operation") -> 0 | Q5: =COUNTIFS(Week,'Adherence Omnia'!Q$3,Agent_ID,'Adherence Omnia'!$B5,TargeType,"Agent Level",Queue,$C$2,DEP,"Operation") -> 0 | R5: =SUM(N5:Q5)>=SUM(J5:M5) -> FALSE | S5: =IFERROR(SUM(N4:Q4)/SUM(J4:M4),"") -> 0.5
